# Issue 202504070037

## Code

- git hash: b288a593
- branch: cmaes-discrete

## Error Message

```commandline
Traceback (most recent call last):
  File "C:\Users\csilab\Workspace\ICAP\scheme\cmaes_discrete\src\main.py", line 31, in <module>
    main()
  File "C:\Users\csilab\Workspace\ICAP\scheme\cmaes_discrete\src\main.py", line 27, in main
    analysis.plot_loss(settings, dump, os.path.join(save_dir, "loss.pdf"))
  File "C:\Users\csilab\Workspace\ICAP\scheme\cmaes_discrete\src\analysis.py", line 34, in plot_loss
    fig.legend(handles=[loss_line_r, loss_line_n], loc='lower center')
  File "C:\Users\csilab\AppData\Local\pypoetry\Cache\virtualenvs\interpretable-controller-for-analyzing-phe-eBDQW-UP-py3.12\Lib\site-packages\matplotlib\figure.py", line 1134, in legend
    handles, labels, kwargs = mlegend._parse_legend_args(self.axes, *args, **kwargs)
                              ^^^^^^^^^^^^^^^^^^^^^^^^^^^^^^^^^^^^^^^^^^^^^^^^^^^^^^
  File "C:\Users\csilab\AppData\Local\pypoetry\Cache\virtualenvs\interpretable-controller-for-analyzing-phe-eBDQW-UP-py3.12\Lib\site-packages\matplotlib\legend.py", line 1339, in _parse_legend_args
    labels = [handle.get_label() for handle in handles]
              ^^^^^^^^^^^^^^^^
AttributeError: 'list' object has no attribute 'get_label'
```